Workbook

Sheet How to use
A1: How to use
A3: Dashboard' tab
A4: The dashboard provides a high-level summary of all activities from the Activities tab. It displays: Total number of activities Number of completed and outstanding tasks Progress by workstream Outstanding tasks by owner Use the dashboard to quickly understand overall event readiness and identify areas that require attention.
A6: Activities' tab
A8: Terms | B8: Description
A9: Activities | B9: The full list of tasks required to plan and execute the event
A10: Workstream | B10: Grouping of related activities by phase of the event (e.g., Pre-Event Planning, Logistics, Day-of)
A11: Activity | B11: A specific task that needs to be completed within a workstream
A12: What "Done" looks like | B12: Clear definition of what successful completion of the activity looks like
A13: Due Date | B13: The deadline by which the activity should be completed
A14: Ownership | B14: The assigned individual responsible for completing the activity. Update 'Dashboard' tab cells 20–29 to ensure owners are correctly linked
A15: Status | B15: When activity has been completed, indicate as complete

Sheet Dashboard
A1: Event Workback Plan Dashboard
A2: Event Date: | B2: 46260
A3: Event Countdown | B3: =B2-TODAY() -> 1
A5: Total Tasks | C5: Completed Tasks | E5: Outstanding Tasks
A6: =COUNTA('OLD Activities'!C4:C497) -> 43 | C6: =COUNTIF('OLD Activities'!L2:L497,"Complete") -> 2 | E6: =A6-C6 -> 41
A9: Workstream Summary | B9: =SUM(C11:C16)/A6 -> 0.046511628
A10: Workstream | B10: Total Activities | C10: Completed Activities | D10: Outstanding Activities
A11: Pre-Event Planning | B11: =COUNTIF('OLD Activities'!B2:B497,A11) -> 7 | C11: =COUNTIFS('OLD Activities'!B2:B497,A11,'OLD Activities'!L2:L497,"Complete") -> 2 | D11: =B11-C11 -> 5
A12: Outreach & Registration | B12: =COUNTIF('OLD Activities'!B2:B497,A12) -> 8 | C12: =COUNTIFS('OLD Activities'!B2:B497,A12,'OLD Activities'!L2:L497,"Complete") -> 0 | D12: =B12-C12 -> 8
A13: Pre-Event Logistics | B13: =COUNTIF('OLD Activities'!B2:B497,A13) -> 8 | C13: =COUNTIFS('OLD Activities'!B2:B497,A13,'OLD Activities'!L2:L497,"Complete") -> 0 | D13: =B13-C13 -> 8
A14: 1 Week Prior Event Planning | B14: =COUNTIF('OLD Activities'!B2:B497,A14) -> 10 | C14: =COUNTIFS('OLD Activities'!B2:B497,A14,'OLD Activities'!L2:L497,"Complete") -> 0 | D14: =B14-C14 -> 10
A15: Day-of Event Execution | B15: =COUNTIF('OLD Activities'!B2:B497,A15) -> 6 | C15: =COUNTIFS('OLD Activities'!B2:B497,A15,'OLD Activities'!L2:L497,"Complete") -> 0 | D15: =B15-C15 -> 6
A16: Post-Event Follow-Up | B16: =COUNTIF('OLD Activities'!B2:B497,A16) -> 4 | C16: =COUNTIFS('OLD Activities'!B2:B497,A16,'OLD Activities'!L2:L497,"Complete") -> 0 | D16: =B16-C16 -> 4
A18: Outstanding Tasks by Owner
A19: Owner | B19: Total Activities | C19: Completed Activities | D19: Outstanding Activities
A20: Owner 1 | B20: =COUNTIF('OLD Activities'!$K$4:$K$166,A20) -> 3 | C20: =COUNTIFS('OLD Activities'!$K$4:$K$164,A20,'OLD Activities'!$L$4:$L$164,"Complete") -> 1 | D20: =COUNTIFS('OLD Activities'!$K$4:$K$170,Dashboard!A20,'OLD Activities'!$L$4:$L$170,"<>Complete") -> 2
A21: Owner 2 | B21: =COUNTIF('OLD Activities'!$K$4:$K$166,A21) -> 1 | C21: =COUNTIFS('OLD Activities'!$K$4:$K$164,A21,'OLD Activities'!$L$4:$L$164,"Complete") -> 1 | D21: =COUNTIFS('OLD Activities'!$K$4:$K$170,Dashboard!A21,'OLD Activities'!$L$4:$L$170,"<>Complete") -> 0
A22: Owner 3 | B22: =COUNTIF('OLD Activities'!$K$4:$K$166,A22) -> 1 | C22: =COUNTIFS('OLD Activities'!$K$4:$K$164,A22,'OLD Activities'!$L$4:$L$164,"Complete") -> 0 | D22: =COUNTIFS('OLD Activities'!$K$4:$K$170,Dashboard!A22,'OLD Activities'!$L$4:$L$170,"<>Complete") -> 1
A23: Owner 4 | B23: =COUNTIF('OLD Activities'!$K$4:$K$166,A23) -> 0 | C23: =COUNTIFS('OLD Activities'!$K$4:$K$164,A23,'OLD Activities'!$L$4:$L$164,"Complete") -> 0 | D23: =COUNTIFS('OLD Activities'!$K$4:$K$170,Dashboard!A23,'OLD Activities'!$L$4:$L$170,"<>Complete") -> 0
A24: Owner 5 | B24: =COUNTIF('OLD Activities'!$K$4:$K$166,A24) -> 0 | C24: =COUNTIFS('OLD Activities'!$K$4:$K$164,A24,'OLD Activities'!$L$4:$L$164,"Complete") -> 0 | D24: =COUNTIFS('OLD Activities'!$K$4:$K$170,Dashboard!A24,'OLD Activities'!$L$4:$L$170,"<>Complete") -> 0
A25: Owner 6 | B25: =COUNTIF('OLD Activities'!$K$4:$K$166,A25) -> 0 | C25: =COUNTIFS('OLD Activities'!$K$4:$K$164,A25,'OLD Activities'!$L$4:$L$164,"Complete") -> 0 | D25: =COUNTIFS('OLD Activities'!$K$4:$K$170,Dashboard!A25,'OLD Activities'!$L$4:$L$170,"<>Complete") -> 0
A26: Owner 7 | B26: =COUNTIF('OLD Activities'!$K$4:$K$166,A26) -> 0 | C26: =COUNTIFS('OLD Activities'!$K$4:$K$164,A26,'OLD Activities'!$L$4:$L$164,"Complete") -> 0 | D26: =COUNTIFS('OLD Activities'!$K$4:$K$170,Dashboard!A26,'OLD Activities'!$L$4:$L$170,"<>Complete") -> 0
A27: Owner 8 | B27: =COUNTIF('OLD Activities'!$K$4:$K$166,A27) -> 0 | C27: =COUNTIFS('OLD Activities'!$K$4:$K$164,A27,'OLD Activities'!$L$4:$L$164,"Complete") -> 0 | D27: =COUNTIFS('OLD Activities'!$K$4:$K$170,Dashboard!A27,'OLD Activities'!$L$4:$L$170,"<>Complete") -> 0
A28: Owner 9 | B28: =COUNTIF('OLD Activities'!$K$4:$K$166,A28) -> 0 | C28: =COUNTIFS('OLD Activities'!$K$4:$K$164,A28,'OLD Activities'!$L$4:$L$164,"Complete") -> 0 | D28: =COUNTIFS('OLD Activities'!$K$4:$K$170,Dashboard!A28,'OLD Activities'!$L$4:$L$170,"<>Complete") -> 0
A29: Owner 10 | B29: =COUNTIF('OLD Activities'!$K$4:$K$166,A29) -> 0 | C29: =COUNTIFS('OLD Activities'!$K$4:$K$164,A29,'OLD Activities'!$L$4:$L$164,"Complete") -> 0 | D29: =COUNTIFS('OLD Activities'!$K$4:$K$170,Dashboard!A29,'OLD Activities'!$L$4:$L$170,"<>Complete") -> 0

Sheet Gantt Chart
A1: 10 Weeks
A2: 4 weeks | B2: Agenda

Sheet ACTIVITIES NEW
A1: Event Workback Plan
A2: Action | B2: Workstream | C2: Activity (START WITH VERB) | D2: What "Done" Looks Like | E2: Dependencies | F2: Estimated Time Taken (Start to Finish: ~10 weeks) | G2: Start Date (year-mm-dd) | H2: End Date (year-mm-dd) | I2: Duration | J2: Actual End Date (year-mm-dd) | K2: Ownership | L2: Status (Complete/In Progress) | M2: Notes
A3: =ROW() - ROW($A$3) + 1 -> 1 | B3: Agenda and Topic Finalization | C3: Receive event request from leadership | D3: Email receieved from leadership on event objective and estimated venue date | E3: None
A4: =ROW() - ROW($A$3) + 1 -> 2 | B4: Agenda and Topic Finalization | C4: Discuss anticipated attendees | D4: Defined attendee profile and attendance target | E4: None
A5: =ROW() - ROW($A$3) + 1 -> 3 | B5: Agenda and Topic Finalization | C5: Discuss whether the event will be organized with an external partner | D5: Confirmed participation of an external partner and expected contribution | E5: None
A6: =ROW() - ROW($A$3) + 1 -> 4 | B6: Agenda and Topic Finalization | C6: If working with external partners, clarify roles, responsibilities, and expectations | D6: Documented agreed partner responsibilities, attendee targets and speaking roles | E6: None
A7: =ROW() - ROW($A$3) + 1 -> 5 | B7: Agenda and Topic Finalization | C7: Discuss the detailed event topic and agenda with leadership (Lisa C., Kevin L., etc.) | D7: Aligned event objectives, discussion topics, session structure, and duration | E7: None
A8: =ROW() - ROW($A$3) + 1 -> 6 | B8: Agenda and Topic Finalization | C8: Draft the event topic and agenda based on leadership input | D8: Completed draft agenda including objectives, topics, speakers, and timings | E8: #5 – Leadership alignment on event objectives and discussion topics is required before drafting the agenda
A9: =ROW() - ROW($A$3) + 1 -> 7 | B9: Agenda and Topic Finalization | C9: Review the event topic and agenda with leadership (Stanley C., etc.) | D9: Incorporated leadership feedback into the draft agenda
A10: =ROW() - ROW($A$3) + 1 -> 8 | B10: Agenda and Topic Finalization | C10: Obtain leadership approval of the event topic and agenda (Lisa C., Kevin L., etc.) | D10: Finalized and approved the event agenda for distribution
A11: =ROW() - ROW($A$3) + 1 -> 9 | B11: Agenda and Topic Finalization | C11: Milestone 1 – Attendee Count and Agenda Confirmed | D11: Confirmed attendee targets and approved agenda
A12: =ROW() - ROW($A$3) + 1 -> 10 | B12: Room and Catering Finalization | C12: Check room availability (Deloitte or external venue) for the proposed event date | D12: Identified venue options and confirmed availability | E12: #8 – Approved event duration are needed before evaluating venue options
A13: =ROW() - ROW($A$3) + 1 -> 11 | B13: Room and Catering Finalization | C13: Confirm date availability with leadership (Lisa C., Kevin L., etc.) | D13: Aligned with leadership on venue availability | E13: #10 – Available venue options should be reviewed before finalizing the event date
A14: =ROW() - ROW($A$3) + 1 -> 12 | B14: Room and Catering Finalization | C14: Book the event space (conference room and social space) and reserve a registration table in the lobby | D14: Secured venue booking and registration table reservation
A15: =ROW() - ROW($A$3) + 1 -> 13 | B15: Room and Catering Finalization | C15: Estimate the food and beverage budget for the event | D15: Developed catering budget based on attendance estimates and event format | E15: #2, #10 – Attendance estimates drive catering quantities, and the event date and format affect catering requirements and pricing
A16: =ROW() - ROW($A$3) + 1 -> 14 | B16: Room and Catering Finalization | C16: Share the food and beverage budget with leadership for approval | D16: Approved catering budget for event planning purposes
A17: =ROW() - ROW($A$3) + 1 -> 15 | B17: Room and Catering Finalization | C17: Arrange catering services | D17: Confirmed menu selections, service times, attendee counts, and catering order | E17: #14 – Budget approval is required before catering services can be confirmed
A18: =ROW() - ROW($A$3) + 1 -> 16 | B18: Room and Catering Finalization | C18: Milestone 2 – Room Booking and Catering Confirmed | D18: Confirmed venue, registration table, and catering arrangements
A19: =ROW() - ROW($A$3) + 1 -> 17 | B19: Invitation Material Finalization | C19: Send a placeholder calendar (date, time) invite to Deloitte leadership and the organizing team | D19: Distributed placeholder calendar invite with confirmed date and time | E19: #12 – The event date should be confirmed before holding attendees' calendars
A20: =ROW() - ROW($A$3) + 1 -> 18 | B20: Invitation Material Finalization | C20: Draft the calendar invitation, including event details and agenda | D20: Prepared calendar invitation with approved agenda, venue details, and attendee instructions | E20: #8, #12 – The agenda should be approved and venue details confirmed before draft inivitation email
A21: =ROW() - ROW($A$3) + 1 -> 19 | B21: Invitation Material Finalization | C21: Review the calendar invitation with leadership (Stanley C., etc.) | D21: Incorporated leadership feedback into the calendar invitation
A22: =ROW() - ROW($A$3) + 1 -> 20 | B22: Invitation Material Finalization | C22: Send the calendar invitation to the organizing team, external partners, and Deloitte leadership | D22: Distributed calendar invitation to organizers, leadership, external partners, and attendees
A23: =ROW() - ROW($A$3) + 1 -> 21 | B23: Invitation Material Finalization | C23: Draft the thank-you email | D23: Prepared thank-you email including event agenda and discussion topic | E23: None
A24: =ROW() - ROW($A$3) + 1 -> 22 | B24: Invitation Material Finalization | C24: Review and obtain approval of the thank-you email from leadership (Stanley C., etc.) | D24: Approved thank-you email for post-event distribution
A25: =ROW() - ROW($A$3) + 1 -> 23 | B25: Invitation Material Finalization | C25: Milestone 3 – Invitation Materials Finalized | D25: Finalized invitation materials and post-event communications
A26: =ROW() - ROW($A$3) + 1 -> 24 | B26: Material Finalization | C26: Draft the presentation deck template | D26: Created presentation template aligned with Deloitte branding standards | E26: #8 – The agenda should be approved before presentation materials are developed
A27: =ROW() - ROW($A$3) + 1 -> 25 | B27: Material Finalization | C27: Share the draft presentation deck with designated slide owners | D27: Assigned slide ownership and distributed presentation materials
A28: =ROW() - ROW($A$3) + 1 -> 26 | B28: Material Finalization | C28: Perform QA Review #1 of the presentation deck to ensure content flow and consistency | D28: Verified content flow, formatting consistency, and branding compliance | E28: #24 – Presentation content should be developed before quality assurance can be performed
A29: =ROW() - ROW($A$3) + 1 -> 27 | B29: Material Finalization | C29: Review presentation materials with leadership (Stanley C., etc.) | D29: Incorporated leadership feedback into presentation materials
A30: =ROW() - ROW($A$3) + 1 -> 28 | B30: Material Finalization | C30: Obtain leadership approval of presentation materials (Lisa C., Kevin L., etc.) | D30: Approved presentation materials for event delivery
A31: =ROW() - ROW($A$3) + 1 -> 29 | B31: Material Finalization | C31: Milestone 4 – Presentation Deck Finalized | D31: Finalized presentation materials for event delivery
A32: =ROW() - ROW($A$3) + 1 -> 30 | B32: Pre-Event Planning | C32: Set up a shared folder and supporting templates | D32: Created centralized workspace with folders, templates, and trackers accessible to event organizers | E32: None
A33: =ROW() - ROW($A$3) + 1 -> 31 | B33: Pre-Event Planning | C33: Create a Teams group chat for Deloitte event organizers | D33: Established communication channel and add all organizers. | E33: None
A34: =ROW() - ROW($A$3) + 1 -> 32 | B34: Pre-Event Planning | C34: Schedule weekly stand-up meetings with event organizers | D34: Scheduled recurring meetings and communicated attendance expectations | E34: None
A35: =ROW() - ROW($A$3) + 1 -> 33 | B35: Outreach and Registration | C35: Set up the registration link (e.g., DU Tracker) | D35: Configured and tested registration platform | E35: None
A36: =ROW() - ROW($A$3) + 1 -> 34 | B36: Outreach and Registration | C36: Distribute the registration link to attendees | D36: Sent registration link to intended attendees | E36: #33 – The registration platform should be tested before distribution
A37: =ROW() - ROW($A$3) + 1 -> 35 | B37: Outreach and Registration | C37: Milestone 5 – Registration Opened | D37: Opened attendee registration process
A38: =ROW() - ROW($A$3) + 1 -> 36 | B38: Outreach and Registration | C38: Download the attendee registration report from the registration platform | D38: Generated attendee registration report for reconciliation purposes
A39: =ROW() - ROW($A$3) + 1 -> 37 | B39: Outreach and Registration | C39: Share the registration list with leadership (Lisa C., Kevin L., etc.) | D39: Provided leadership with attendee registration status and attendance trends | E39: #33 – Registration data should be available before sharing attendee status updates
A40: =ROW() - ROW($A$3) + 1 -> 38 | B40: Outreach and Registration | C40: Identify attendees included in the registration list who have not received the calendar invitation | D40: Reconciled registration and invitation lists and identified attendance gaps
...

Sheet Activities (2)
A1: Event Workback Plan
A2: Action | B2: Workstream | C2: Activity (START WITH VERB) | E2: What "Done" Looks Like | F2: Dependencies | G2: Estimated Time Taken (Start to Finish: ~10 weeks) | H2: Start Date (year-mm-dd) | I2: End Date (year-mm-dd) | J2: Duration | K2: Actual End Date (year-mm-dd) | L2: Ownership | M2: Status (Complete/In Progress) | N2: Notes
C3: Coordinate venue, and event with leaders prior to draft agenda ,topic anticipated audience
A4: 1 | B4: Agenda and Topic Finalization | C4: Confirm event format and key logistics | D4: Milestone (budget - people coming, food we need, venue at deloitte or outside) (room - how many people), registration (how many people) | E4: Event scope is fully defined, including confirmed date, target number of attendees, number and type of speakers, and total event duration | F4: N/A | G4: ~ 1 Week | H4: 46223 | I4: 46225 | J4: =_xlfn.DAYS(I4,H4) -> 2 | L4: Owner 1 | M4: Complete
A5: 2 | B5: Agenda and Topic Finalization | C5: Draft budget | D5: Budget -> leader input -> execute orders | E5: Estimated budget covering venue, catering, and additional event materials | F5: #1 - Budget estimates depend on the event format, attendance targets, and logistics requirements. | H5: 46225 | I5: 46228 | J5: =_xlfn.DAYS(I5,H5) -> 3 | L5: Owner 3 | M5: In progress
A6: 3 | B6: =Dashboard!$A$11 -> Pre-Event Planning | C6: Set up shared folder and templates | D6: Agenda -> set up place holders for organizing team + external partner and deloitte leadership | E6: Centralized folder created with clear subfolders (e.g., outreach, logistics, materials) and trackers/templates accessible to all team members | F6: N/A | G6: ~ 1 Day | J6: =_xlfn.DAYS(I6,H6) -> 0 | L6: Owner 2 | M6: Complete
A7: 4 | B7: =Dashboard!$A$11 -> Pre-Event Planning | C7: Send internal invite with key dates and placeholders | E7: Send meeting invite to organizing team. Internal calendar placeholders for the event | F7: N/A | J7: =_xlfn.DAYS(I7,H7) -> 0 | L7: Owner 1
A8: 5 | B8: =Dashboard!$A$11 -> Pre-Event Planning | C8: Create group chat on Teams for Deloitte event organizers | E8: Teams chat created with all event organizers added | F8: N/A | J8: =_xlfn.DAYS(I8,H8) -> 0 | L8: Owner 1
A9: 6 | B9: =Dashboard!$A$11 -> Pre-Event Planning | C9: Schedule weekly stand up calls with event organizers | E9: Confirm tasks has been completed, and next steps | F9: N/A | J9: =_xlfn.DAYS(I9,H9) -> 0
A10: 7 | B10: =Dashboard!$A$11 -> Pre-Event Planning | C10: If working with vendor, clarify responsibilities and expectations | D10: move before milestone event (before finalized agenda) | E10: Vendor roles, attendee targets, and responsibilities clearly agreed | F10: #1, #3 - Event objectives and budget constraints should be understood before engaging vendors. | G10: ~ 1 Week | J10: =_xlfn.DAYS(I10,H10) -> 0
A11: 8 | B11: =Dashboard!$A$12 -> Outreach & Registration | C11: Update Internal attendee coordination | E11: Identify target attendees, align with partners/leaders, and finalize the internal outreach list. | F11: N/A | G11: On going | J11: =_xlfn.DAYS(I11,H11) -> 0
A12: 9 | B12: =Dashboard!$A$12 -> Outreach & Registration | C12: External attendee coordination (if applicable) | E12: Coordinate with the vendor to identify, review, and finalize the external attendee list. | F12: #7 - Vendor responsibilities and attendee expectations must be agreed upon before coordinating outreach. | J12: =_xlfn.DAYS(I12,H12) -> 0
A13: 10 | B13: Agenda and Topic finalization | C13: Draft Agenda | E13: Draft agenda including the event objectives, session topics, timings | F13: N/A | G13: ~ 2 Week | J13: =_xlfn.DAYS(I13,H13) -> 0
A14: 11 | B14: Agenda and Topic finalization | C14: Review and approval of the agenda | E14: Draft agenda approved by leadership with feedback incorporated | F14: N/A | J14: =_xlfn.DAYS(I14,H14) -> 0
A15: 12 | B15: Agenda and Topic finalization | C15: Draft calendar invite | E15: Calendar invite drafted with approved event details, agenda, date, time, venue and attendees instruction | F15: N/A | G15: ~ 1 Week | J15: =_xlfn.DAYS(I15,H15) -> 0
A16: 13 | B16: Agenda and Topic finalization | C16: Send calendar invite | E16: Invite distributed to attendees, with successful delivery confirmed | F16: #11, #12 - Calendar invite and agenda must be finalized before distribution. | J16: =_xlfn.DAYS(I16,H16) -> 0
A17: 14 | B17: =Dashboard!$A$12 -> Outreach & Registration | C17: Track registrations | D17: Set up tracker (i.e., DU tracker) -> collect excel [ASK RILEY] -> send partner and leadership latest list (dates on when its sent out, T-1,T-3 etc.) | E17: Tracker is up to date with confirmed attendees and follow-ups | F17: #13 - Registration tracking begins once invitations are sent. | G17: On going | J17: =_xlfn.DAYS(I17,H17) -> 0
A18: 15 | B18: Agenda and Topic finalization | C18: Confirm catering | E18: Food and drinks scheduled and ready 15 minutes before the designated serving time | F18: #14 - Catering requirements depend on expected attendance. | G18: On going | J18: =_xlfn.DAYS(I18,H18) -> 0
A19: 16 | B19: Agenda and Topic finalization | C19: Book event space, Book room for food and beverage | E19: Main room booked with seating layout (pods) and request for lanyard box for attendees to drop their lanyards after event | F19: #1 - Venue requirements depend on approved event format and attendance targets. | G19: ~ 2 Days | J19: =_xlfn.DAYS(I19,H19) -> 0
A20: 17 | B20: Agenda and Topic finalization | E20: Rooms booked for cocktail/dinner hours, request set up 15min prior to scheduled time | F20: #7 - Food and beverage orders depend on attendance estimates. | J20: =_xlfn.DAYS(I20,H20) -> 0
A21: 18 | B21: =Dashboard!$A$13 -> Pre-Event Logistics | C21: Prepare draft signage | E21: Signage draft in line with Deloitte standards | F21: N/A | G21: ~1 Week | J21: =_xlfn.DAYS(I21,H21) -> 0
B22: =Dashboard!$A$13 -> Pre-Event Logistics | C22: Review and approval of signage with leadership | E22: Signage approved by leadership and IT | F22: N/A
A23: 19 | B23: =Dashboard!$A$13 -> Pre-Event Logistics | C23: Coordinate IT support (videoconferencing capabilities) | E23: IT confirmed to support AV and arrive 30min before event start time | F23: #16 - IT requirements depend on the selected venue and event format. | J23: =_xlfn.DAYS(I23,H23) -> 0
A24: 20 | B24: =Dashboard!$A$13 -> Pre-Event Logistics | C24: Signage (30min before and 30min after event start) | E24: Signage placed 30min before registration opens and 30min after event start time | F24: N/A | J24: =_xlfn.DAYS(I24,H24) -> 0
A25: 21 | B25: =Dashboard!$A$13 -> Pre-Event Logistics | C25: Book registration table | D25: Put all bookings together | E25: Lobby registration table requested and confirmed | F25: N/A | J25: =_xlfn.DAYS(I25,H25) -> 0
A26: 22 | B26: Agenda and Topic finalization | C26: Draft and assign presentation materials to appropriate individual | E26: Draft presentation materials completed, with each slide assigned to the appropriate individual for content development and review. | F26: N/A | J26: =_xlfn.DAYS(I26,H26) -> 0
C27: Review and approval of presentation materials with leadership (Stanley etc.)
A28: 23 | B28: =Dashboard!$A$14 -> 1 Week Prior Event Planning | C28: Review and approval of presentation materials with leadership (Lisa, Kevin etc.) | E28: Presentation materials reviewed by leadership, feedback incorporated, and final approval received for presentation at the event. | F28: #22 - Completion of the presentation materials | G28: ~ 2 Week | J28: =_xlfn.DAYS(I28,H28) -> 0
A29: 24 | B29: =Dashboard!$A$14 -> 1 Week Prior Event Planning | C29: Review Materials (Final QA) | E29: Confirm slide materials has consistent formatting | F29: #22 - Completion of the presentation materials | J29: =_xlfn.DAYS(I29,H29) -> 0
A30: 25 | B30: =Dashboard!$A$14 -> 1 Week Prior Event Planning | C30: Follow up partners for attendees | D30: Sending excel attendees | E30: Follow up with partner to complete and confirm the attendees | F30: N/A | G30: ~ 1 Week | J30: =_xlfn.DAYS(I30,H30) -> 0
A31: 26 | B31: Event Execution Logistics | C31: Confirm Deloitte moderator | E31: Select 1 or 2 individual as a moderator to introduce speakers | F31: N/A | J31: =_xlfn.DAYS(I31,H31) -> 0
A32: 27 | B32: Event Execution Logistics | C32: Prepare questions for Q&A | E32: Set of 12 approved questions ready to guide discussion | F32: N/A | J32: =_xlfn.DAYS(I32,H32) -> 0
A33: 28 | B33: Event Execution Logistics | C33: Do a dry run with partners (handoffs, how long each speak etc.) | D33: show materials, during the meeting the timekeeper will give you 5min signage for remaining, speaking order | E33: Full dry run with speakers and moderators completed with timing and transitions confirmed | F33: #23, #25 – Materials, speaker assignments, and Q&A topics must be finalized before rehearsal. | J33: =_xlfn.DAYS(I33,H33) -> 0
A34: 29 | B34: Event Execution Logistics | C34: Place order for lanyards, podium pass, name trays | E34: Confirm and share the confirmation email with the team. Order 10 extra lanyards | F34: #14 - Attendance estimates are needed to determine quantities. | G34: On going | J34: =_xlfn.DAYS(I34,H34) -> 0
A35: 30 | B35: Event Execution Logistics | C35: Place order for name tags | E35: Confirm and share the confirmation email with the team. Order 10 blank name tags | F35: #14 - Attendance estimates are needed to determine quantities. | J35: =_xlfn.DAYS(I35,H35) -> 0
A36: 31 | B36: Event Execution Logistics | C36: Draft 'thank you' email - moved up | D36: Once agenda is finalized | E36: Draft 'thank you' email including the key discussion topics | F36: N/A | G36: ~ 3 Days | J36: =_xlfn.DAYS(I36,H36) -> 0
A37: 32 | B37: Event Execution Logistics | C37: Review and approval of 'thank you' email - moved up | E37: Draft 'thank you' email approved by leadership with feedback incorporated | F37: N/A | J37: =_xlfn.DAYS(I37,H37) -> 0
A38: 33 | B38: Event Execution Logistics | C38: Assign note takers for meeting summary (Q&A) | E38: Draft summary of questions and answers during the presentation | F38: N/A | G38: ~ 1 Day | J38: =_xlfn.DAYS(I38,H38) -> 0
A39: 34 | B39: Day of roles | C39: Attendee Flow Coordinator (if necessary) | E39: Escort attendees from one room to another | F39: N/A | J39: =_xlfn.DAYS(I39,H39) -> 0
A40: 35 | B40: Day of roles | C40: Timekeeper (align signage with speakers) | E40: Provide a heads-up when speakers have 5 minutes left. Confirm with speakers the signal that will be used | F40: N/A | J40: =_xlfn.DAYS(I40,H40) -> 0
...

Sheet Team Coordination
A1: Role | B1: Quantity | C1: What they do | E1: * Roles we need on the day of
A2: Logistic Team Leader
A3: IT support person
A4: Catering person
A5: Elevator Runners + Attendee flow coordinator | B5: 1
A6: Registration booth | B6: 2 | C6: 1 guide guest, 1 check in quest
A7: Time keeper + Mic runner | B7: 1 | C7: sign during meeting
A8: Moderator
A9: Slide Assistant
A10: Note Taker | C10: for meeting summary

Sheet OLD Activities
A1: Event Workback Plan
A2: Action | B2: Workstream | C2: Activity | D2: What "Done" Looks Like | E2: Dependencies | F2: Estimated Time Taken (Start to Finish: ~10 weeks) | G2: Start Date (year-mm-dd) | H2: End Date (year-mm-dd) | I2: Duration | J2: Actual End Date (year-mm-dd) | K2: Ownership | L2: Status (Complete/In Progress) | M2: Notes
C3: Coordinate venue, and event with leaders prior to draft agenda ,topic anticipated audience
A4: 1 | B4: =Dashboard!$A$11 -> Pre-Event Planning | C4: Confirm event format and key logistics | D4: Event scope is fully defined, including confirmed date, target number of attendees, number and type of speakers, and total event duration | E4: N/A | F4: ~ 1 Week | G4: 46223 | H4: 46225 | I4: =_xlfn.DAYS(H4,G4) -> 2 | K4: Owner 1 | L4: Complete
A5: 2 | B5: =Dashboard!$A$11 -> Pre-Event Planning | C5: Draft budget | D5: Estimated budget covering venue, catering, and additional event materials | E5: #1 - Budget estimates depend on the event format, attendance targets, and logistics requirements. | G5: 46225 | H5: 46228 | I5: =_xlfn.DAYS(H5,G5) -> 3 | K5: Owner 3 | L5: In progress
A6: 3 | B6: =Dashboard!$A$11 -> Pre-Event Planning | C6: Set up shared folder and templates | D6: Centralized folder created with clear subfolders (e.g., outreach, logistics, materials) and trackers/templates accessible to all team members | E6: N/A | F6: ~ 1 Day | I6: =_xlfn.DAYS(H6,G6) -> 0 | K6: Owner 2 | L6: Complete
A7: 4 | B7: =Dashboard!$A$11 -> Pre-Event Planning | C7: Send internal invite with key dates and placeholders | D7: Send meeting invite to organizing team. Internal calendar placeholders for the event | E7: N/A | I7: =_xlfn.DAYS(H7,G7) -> 0 | K7: Owner 1
A8: 5 | B8: =Dashboard!$A$11 -> Pre-Event Planning | C8: Group chat on Teams for Deloitte event organizers | D8: Teams chat created with all event organizers added | E8: N/A | I8: =_xlfn.DAYS(H8,G8) -> 0 | K8: Owner 1
A9: 6 | B9: =Dashboard!$A$11 -> Pre-Event Planning | C9: Schedule weekly stand up calls with event organizers | D9: Confirm tasks has been completed, and next steps | E9: N/A | I9: =_xlfn.DAYS(H9,G9) -> 0
A10: 7 | B10: =Dashboard!$A$11 -> Pre-Event Planning | C10: If working with vendor, clarify responsibilities and expectations | D10: Vendor roles, attendee targets, and responsibilities clearly agreed | E10: #1, #3 - Event objectives and budget constraints should be understood before engaging vendors. | F10: ~ 1 Week | I10: =_xlfn.DAYS(H10,G10) -> 0
A11: 8 | B11: =Dashboard!$A$12 -> Outreach & Registration | C11: Update Internal attendee coordination | D11: Identify target attendees, align with partners/leaders, and finalize the internal outreach list. | E11: N/A | F11: On going | I11: =_xlfn.DAYS(H11,G11) -> 0
A12: 9 | B12: =Dashboard!$A$12 -> Outreach & Registration | C12: External attendee coordination (if applicable) | D12: Coordinate with the vendor to identify, review, and finalize the external attendee list. | E12: #7 - Vendor responsibilities and attendee expectations must be agreed upon before coordinating outreach. | I12: =_xlfn.DAYS(H12,G12) -> 0
A13: 10 | B13: =Dashboard!$A$12 -> Outreach & Registration | C13: Draft Agenda | D13: Draft agenda including the event objectives, session topics, timings | E13: N/A | F13: ~ 2 Week | I13: =_xlfn.DAYS(H13,G13) -> 0
A14: 11 | B14: =Dashboard!$A$12 -> Outreach & Registration | C14: Review and approval of the agenda | D14: Draft agenda approved by leadership with feedback incorporated | E14: N/A | I14: =_xlfn.DAYS(H14,G14) -> 0
A15: 12 | B15: =Dashboard!$A$12 -> Outreach & Registration | C15: Draft calendar invite | D15: Calendar invite drafted with approved event details, agenda, date, time, venue and attendees instruction | E15: N/A | F15: ~ 1 Week | I15: =_xlfn.DAYS(H15,G15) -> 0
A16: 13 | B16: =Dashboard!$A$12 -> Outreach & Registration | C16: Send calendar invite | D16: Invite distributed to attendees, with successful delivery confirmed | E16: #11, #12 - Calendar invite and agenda must be finalized before distribution. | I16: =_xlfn.DAYS(H16,G16) -> 0
A17: 14 | B17: =Dashboard!$A$12 -> Outreach & Registration | C17: Track registrations | D17: Tracker is up to date with confirmed attendees and follow-ups | E17: #13 - Registration tracking begins once invitations are sent. | F17: On going | I17: =_xlfn.DAYS(H17,G17) -> 0
A18: 15 | B18: =Dashboard!$A$12 -> Outreach & Registration | C18: Confirm catering | D18: Food and drinks scheduled and ready 15 minutes before the designated serving time | E18: #14 - Catering requirements depend on expected attendance. | F18: On going | I18: =_xlfn.DAYS(H18,G18) -> 0
A19: 16 | B19: =Dashboard!$A$13 -> Pre-Event Logistics | C19: Book event space | D19: Main room booked with seating layout (pods) and request for lanyard box for attendees to drop their lanyards after event | E19: #1 - Venue requirements depend on approved event format and attendance targets. | F19: ~ 2 Days | I19: =_xlfn.DAYS(H19,G19) -> 0
A20: 17 | B20: =Dashboard!$A$13 -> Pre-Event Logistics | C20: Book room for food and beverage | D20: Rooms booked for cocktail/dinner hours, request set up 15min prior to scheduled time | E20: #7 - Food and beverage orders depend on attendance estimates. | I20: =_xlfn.DAYS(H20,G20) -> 0
A21: 18 | B21: =Dashboard!$A$13 -> Pre-Event Logistics | C21: Prepare draft signage | D21: Signage draft in line with Deloitte standards | E21: N/A | F21: ~1 Week | I21: =_xlfn.DAYS(H21,G21) -> 0
B22: =Dashboard!$A$13 -> Pre-Event Logistics | C22: Review and approval of signage with leadership | D22: Signage approved by leadership and IT | E22: N/A
A23: 19 | B23: =Dashboard!$A$13 -> Pre-Event Logistics | C23: Coordinate IT support (videoconferencing capabilities) | D23: IT confirmed to support AV and arrive 30min before event start time | E23: #16 - IT requirements depend on the selected venue and event format. | I23: =_xlfn.DAYS(H23,G23) -> 0
A24: 20 | B24: =Dashboard!$A$13 -> Pre-Event Logistics | C24: Signage (30min before and 30min after event start) | D24: Signage placed 30min before registration opens and 30min after event start time | E24: N/A | I24: =_xlfn.DAYS(H24,G24) -> 0
A25: 21 | B25: =Dashboard!$A$13 -> Pre-Event Logistics | C25: Book registration table | D25: Lobby registration table requested and confirmed | E25: N/A | I25: =_xlfn.DAYS(H25,G25) -> 0
A26: 22 | B26: =Dashboard!$A$13 -> Pre-Event Logistics | C26: Draft and assign presentation materials to appropriate individual | D26: Draft presentation materials completed, with each slide assigned to the appropriate individual for content development and review. | E26: N/A | I26: =_xlfn.DAYS(H26,G26) -> 0
A27: 23 | B27: =Dashboard!$A$14 -> 1 Week Prior Event Planning | C27: Review and approval of presentation materials with leadership | D27: Presentation materials reviewed by leadership, feedback incorporated, and final approval received for presentation at the event. | E27: #22 - Completion of the presentation materials | F27: ~ 2 Week | I27: =_xlfn.DAYS(H27,G27) -> 0
A28: 24 | B28: =Dashboard!$A$14 -> 1 Week Prior Event Planning | C28: Review Materials (Final QA) | D28: Confirm slide materials has consistent formatting | E28: #22 - Completion of the presentation materials | I28: =_xlfn.DAYS(H28,G28) -> 0
A29: 25 | B29: =Dashboard!$A$14 -> 1 Week Prior Event Planning | C29: Follow up partners for attendees | D29: Follow up with partner to complete and confirm the attendees | E29: N/A | F29: ~ 1 Week | I29: =_xlfn.DAYS(H29,G29) -> 0
A30: 26 | B30: =Dashboard!$A$14 -> 1 Week Prior Event Planning | C30: Confirm Deloitte moderator | D30: Select 1 or 2 individual as a moderator to introduce speakers | E30: N/A | I30: =_xlfn.DAYS(H30,G30) -> 0
A31: 27 | B31: =Dashboard!$A$14 -> 1 Week Prior Event Planning | C31: Prepare questions for Q&A | D31: Set of 12 approved questions ready to guide discussion | E31: N/A | I31: =_xlfn.DAYS(H31,G31) -> 0
A32: 28 | B32: =Dashboard!$A$14 -> 1 Week Prior Event Planning | C32: Do a dry run with partners (handoffs, how long each speak etc.) | D32: Full dry run with speakers and moderators completed with timing and transitions confirmed | E32: #23, #25 – Materials, speaker assignments, and Q&A topics must be finalized before rehearsal. | I32: =_xlfn.DAYS(H32,G32) -> 0
A33: 29 | B33: =Dashboard!$A$14 -> 1 Week Prior Event Planning | C33: Place order for lanyards, podium pass, name trays | D33: Confirm and share the confirmation email with the team. Order 10 extra lanyards | E33: #14 - Attendance estimates are needed to determine quantities. | F33: On going | I33: =_xlfn.DAYS(H33,G33) -> 0
A34: 30 | B34: =Dashboard!$A$14 -> 1 Week Prior Event Planning | C34: Place order for name tags | D34: Confirm and share the confirmation email with the team. Order 10 blank name tags | E34: #14 - Attendance estimates are needed to determine quantities. | I34: =_xlfn.DAYS(H34,G34) -> 0
A35: 31 | B35: =Dashboard!$A$14 -> 1 Week Prior Event Planning | C35: Draft 'thank you' email | D35: Draft 'thank you' email including the key discussion topics | E35: N/A | F35: ~ 3 Days | I35: =_xlfn.DAYS(H35,G35) -> 0
A36: 32 | B36: =Dashboard!$A$14 -> 1 Week Prior Event Planning | C36: Review and approval of 'thank you' email | D36: Draft 'thank you' email approved by leadership with feedback incorporated | E36: N/A | I36: =_xlfn.DAYS(H36,G36) -> 0
A37: 33 | B37: =Dashboard!$A$15 -> Day-of Event Execution | C37: Assign note takers for meeting summary (Q&A) | D37: Draft summary of questions and answers during the presentation | E37: N/A | F37: ~ 1 Day | I37: =_xlfn.DAYS(H37,G37) -> 0
A38: 34 | B38: =Dashboard!$A$15 -> Day-of Event Execution | C38: Attendee Flow Coordinator (if necessary) | D38: Escort attendees from one room to another | E38: N/A | I38: =_xlfn.DAYS(H38,G38) -> 0
A39: 35 | B39: =Dashboard!$A$15 -> Day-of Event Execution | C39: Timekeeper (align signage with speakers) | D39: Provide a heads-up when speakers have 5 minutes left. Confirm with speakers the signal that will be used | E39: N/A | I39: =_xlfn.DAYS(H39,G39) -> 0
A40: 36 | B40: =Dashboard!$A$15 -> Day-of Event Execution | C40: Registration table (1x: guide guest, 1x check in, 1x event floor guiding to room) | D40: Prepare name tags in trays and arrange them in alphabetical order (by last name); 1x guide guests from the registration table to the elevators, 1x check in attendees (attach name tags to lanyards), 1x floor guide to escort attendees to the room | E40: N/A | I40: =_xlfn.DAYS(H40,G40) -> 0
...

Sheet Activities
A1: Event Workback Plan
A2: Action | B2: Workstream | C2: Activity (START WITH VERB) | E2: What "Done" Looks Like | F2: Dependencies | G2: Estimated Time Taken (Start to Finish: ~10 weeks) | H2: Start Date (year-mm-dd) | I2: End Date (year-mm-dd) | J2: Duration | K2: Actual End Date (year-mm-dd) | L2: Ownership | M2: Status (Complete/In Progress) | N2: Notes
C3: Coordinate event and venue with leadership prior
C4: Check room availability
C5: Coordinate venue, and event with leaders prior to draft agenda ,topic anticipated audience
A6: 1 | B6: Agenda and Topic Finalization | C6: Confirm event format and key logistics | D6: Milestone (budget - people coming, food we need, venue at deloitte or outside) (room - how many people), registration (how many people) | E6: Event scope is fully defined, including confirmed date, target number of attendees, number and type of speakers, and total event duration | F6: N/A | G6: ~ 1 Week | H6: 46223 | I6: 46225 | J6: =_xlfn.DAYS(I6,H6) -> 2 | L6: Owner 1 | M6: Complete
A7: 2 | B7: Agenda and Topic Finalization | C7: Draft budget | D7: Budget -> leader input -> execute orders | E7: Estimated budget covering venue, catering, and additional event materials | F7: #1 - Budget estimates depend on the event format, attendance targets, and logistics requirements. | H7: 46225 | I7: 46228 | J7: =_xlfn.DAYS(I7,H7) -> 3 | L7: Owner 3 | M7: In progress
A8: 3 | B8: =Dashboard!$A$11 -> Pre-Event Planning | C8: Set up shared folder and templates | D8: Agenda -> set up place holders for organizing team + external partner and deloitte leadership | E8: Centralized folder created with clear subfolders (e.g., outreach, logistics, materials) and trackers/templates accessible to all team members | F8: N/A | G8: ~ 1 Day | J8: =_xlfn.DAYS(I8,H8) -> 0 | L8: Owner 2 | M8: Complete
A9: 4 | B9: =Dashboard!$A$11 -> Pre-Event Planning | C9: Send internal invite with key dates and placeholders | E9: Send meeting invite to organizing team. Internal calendar placeholders for the event | F9: N/A | J9: =_xlfn.DAYS(I9,H9) -> 0 | L9: Owner 1
A10: 5 | B10: =Dashboard!$A$11 -> Pre-Event Planning | C10: Create group chat on Teams for Deloitte event organizers | E10: Teams chat created with all event organizers added | F10: N/A | J10: =_xlfn.DAYS(I10,H10) -> 0 | L10: Owner 1
A11: 6 | B11: =Dashboard!$A$11 -> Pre-Event Planning | C11: Schedule weekly stand up calls with event organizers | E11: Confirm tasks has been completed, and next steps | F11: N/A | J11: =_xlfn.DAYS(I11,H11) -> 0
A12: 7 | B12: =Dashboard!$A$11 -> Pre-Event Planning | C12: If working with vendor, clarify responsibilities and expectations | D12: move before milestone event (before finalized agenda) | E12: Vendor roles, attendee targets, and responsibilities clearly agreed | F12: #1, #3 - Event objectives and budget constraints should be understood before engaging vendors. | G12: ~ 1 Week | J12: =_xlfn.DAYS(I12,H12) -> 0
A13: 8 | B13: =Dashboard!$A$12 -> Outreach & Registration | C13: Update Internal attendee coordination | E13: Identify target attendees, align with partners/leaders, and finalize the internal outreach list. | F13: N/A | G13: On going | J13: =_xlfn.DAYS(I13,H13) -> 0
A14: 9 | B14: =Dashboard!$A$12 -> Outreach & Registration | C14: External attendee coordination (if applicable) | E14: Coordinate with the vendor to identify, review, and finalize the external attendee list. | F14: #7 - Vendor responsibilities and attendee expectations must be agreed upon before coordinating outreach. | J14: =_xlfn.DAYS(I14,H14) -> 0
A15: 10 | B15: Agenda and Topic finalization | C15: Draft Agenda | E15: Draft agenda including the event objectives, session topics, timings | F15: N/A | G15: ~ 2 Week | J15: =_xlfn.DAYS(I15,H15) -> 0
A16: 11 | B16: Agenda and Topic finalization | C16: Review and approval of the agenda | E16: Draft agenda approved by leadership with feedback incorporated | F16: N/A | J16: =_xlfn.DAYS(I16,H16) -> 0
A17: 12 | B17: Agenda and Topic finalization | C17: Draft calendar invite | E17: Calendar invite drafted with approved event details, agenda, date, time, venue and attendees instruction | F17: N/A | G17: ~ 1 Week | J17: =_xlfn.DAYS(I17,H17) -> 0
A18: 13 | B18: Agenda and Topic finalization | C18: Send calendar invite | E18: Invite distributed to attendees, with successful delivery confirmed | F18: #11, #12 - Calendar invite and agenda must be finalized before distribution. | J18: =_xlfn.DAYS(I18,H18) -> 0
A19: 14 | B19: =Dashboard!$A$12 -> Outreach & Registration | C19: Track registrations | D19: Set up tracker (i.e., DU tracker) -> collect excel [ASK RILEY] -> send partner and leadership latest list (dates on when its sent out, T-1,T-3 etc.) | E19: Tracker is up to date with confirmed attendees and follow-ups | F19: #13 - Registration tracking begins once invitations are sent. | G19: On going | J19: =_xlfn.DAYS(I19,H19) -> 0
A20: 15 | B20: Agenda and Topic finalization | C20: Confirm catering | E20: Food and drinks scheduled and ready 15 minutes before the designated serving time | F20: #14 - Catering requirements depend on expected attendance. | G20: On going | J20: =_xlfn.DAYS(I20,H20) -> 0
A21: 16 | B21: Agenda and Topic finalization | C21: Book event space, Book room for food and beverage | E21: Main room booked with seating layout (pods) and request for lanyard box for attendees to drop their lanyards after event | F21: #1 - Venue requirements depend on approved event format and attendance targets. | G21: ~ 2 Days | J21: =_xlfn.DAYS(I21,H21) -> 0
A22: 17 | B22: Agenda and Topic finalization | E22: Rooms booked for cocktail/dinner hours, request set up 15min prior to scheduled time | F22: #7 - Food and beverage orders depend on attendance estimates. | J22: =_xlfn.DAYS(I22,H22) -> 0
A23: 18 | B23: =Dashboard!$A$13 -> Pre-Event Logistics | C23: Prepare draft signage | E23: Signage draft in line with Deloitte standards | F23: N/A | G23: ~1 Week | J23: =_xlfn.DAYS(I23,H23) -> 0
B24: =Dashboard!$A$13 -> Pre-Event Logistics | C24: Review and approval of signage with leadership | E24: Signage approved by leadership and IT | F24: N/A
A25: 19 | B25: =Dashboard!$A$13 -> Pre-Event Logistics | C25: Coordinate IT support (videoconferencing capabilities) | E25: IT confirmed to support AV and arrive 30min before event start time | F25: #16 - IT requirements depend on the selected venue and event format. | J25: =_xlfn.DAYS(I25,H25) -> 0
A26: 20 | B26: =Dashboard!$A$13 -> Pre-Event Logistics | C26: Signage (30min before and 30min after event start) | E26: Signage placed 30min before registration opens and 30min after event start time | F26: N/A | J26: =_xlfn.DAYS(I26,H26) -> 0
A27: 21 | B27: =Dashboard!$A$13 -> Pre-Event Logistics | C27: Book registration table | D27: Put all bookings together | E27: Lobby registration table requested and confirmed | F27: N/A | J27: =_xlfn.DAYS(I27,H27) -> 0
A28: 22 | B28: Agenda and Topic finalization | C28: Draft and assign presentation materials to appropriate individual | E28: Draft presentation materials completed, with each slide assigned to the appropriate individual for content development and review. | F28: N/A | J28: =_xlfn.DAYS(I28,H28) -> 0
C29: Review and approval of presentation materials with leadership (Stanley etc.)
A30: 23 | B30: =Dashboard!$A$14 -> 1 Week Prior Event Planning | C30: Review and approval of presentation materials with leadership (Lisa, Kevin etc.) | E30: Presentation materials reviewed by leadership, feedback incorporated, and final approval received for presentation at the event. | F30: #22 - Completion of the presentation materials | G30: ~ 2 Week | J30: =_xlfn.DAYS(I30,H30) -> 0
A31: 24 | B31: =Dashboard!$A$14 -> 1 Week Prior Event Planning | C31: Review Materials (Final QA) | E31: Confirm slide materials has consistent formatting | F31: #22 - Completion of the presentation materials | J31: =_xlfn.DAYS(I31,H31) -> 0
A32: 25 | B32: =Dashboard!$A$14 -> 1 Week Prior Event Planning | C32: Follow up partners for attendees | D32: Sending excel attendees | E32: Follow up with partner to complete and confirm the attendees | F32: N/A | G32: ~ 1 Week | J32: =_xlfn.DAYS(I32,H32) -> 0
A33: 26 | B33: Event Execution Logistics | C33: Confirm Deloitte moderator | E33: Select 1 or 2 individual as a moderator to introduce speakers | F33: N/A | J33: =_xlfn.DAYS(I33,H33) -> 0
A34: 27 | B34: Event Execution Logistics | C34: Prepare questions for Q&A | E34: Set of 12 approved questions ready to guide discussion | F34: N/A | J34: =_xlfn.DAYS(I34,H34) -> 0
A35: 28 | B35: Event Execution Logistics | C35: Do a dry run with partners (handoffs, how long each speak etc.) | D35: show materials, during the meeting the timekeeper will give you 5min signage for remaining, speaking order | E35: Full dry run with speakers and moderators completed with timing and transitions confirmed | F35: #23, #25 – Materials, speaker assignments, and Q&A topics must be finalized before rehearsal. | J35: =_xlfn.DAYS(I35,H35) -> 0
A36: 29 | B36: Event Execution Logistics | C36: Place order for lanyards, podium pass, name trays | E36: Confirm and share the confirmation email with the team. Order 10 extra lanyards | F36: #14 - Attendance estimates are needed to determine quantities. | G36: On going | J36: =_xlfn.DAYS(I36,H36) -> 0
A37: 30 | B37: Event Execution Logistics | C37: Place order for name tags | E37: Confirm and share the confirmation email with the team. Order 10 blank name tags | F37: #14 - Attendance estimates are needed to determine quantities. | J37: =_xlfn.DAYS(I37,H37) -> 0
A38: 31 | B38: Event Execution Logistics | C38: Draft 'thank you' email | D38: Once agenda is finalized | E38: Draft 'thank you' email including the key discussion topics | F38: N/A | G38: ~ 3 Days | J38: =_xlfn.DAYS(I38,H38) -> 0
A39: 32 | B39: Event Execution Logistics | C39: Review and approval of 'thank you' email | E39: Draft 'thank you' email approved by leadership with feedback incorporated | F39: N/A | J39: =_xlfn.DAYS(I39,H39) -> 0
A40: 33 | B40: Event Execution Logistics | C40: Assign note takers for meeting summary (Q&A) | E40: Draft summary of questions and answers during the presentation | F40: N/A | G40: ~ 1 Day | J40: =_xlfn.DAYS(I40,H40) -> 0
...

Sheet OLD Activities (2)
A1: Event Workback Plan
A2: Action | B2: Workstream | C2: Activity (START WITH VERB) | E2: What "Done" Looks Like | F2: Dependencies | G2: Estimated Time Taken (Start to Finish: ~10 weeks) | H2: Start Date (year-mm-dd) | I2: End Date (year-mm-dd) | J2: Duration | K2: Actual End Date (year-mm-dd) | L2: Ownership | M2: Status (Complete/In Progress) | N2: Notes
C3: Coordinate venue, and event with leaders prior to draft agenda ,topic anticipated audience
A4: 1 | B4: Agenda and Topic finalization | C4: Confirm event format and key logistics | D4: Milestone (budget - people coming, food we need, venue at deloitte or outside) (room - how many people), registration (how many people) | E4: Event scope is fully defined, including confirmed date, target number of attendees, number and type of speakers, and total event duration | F4: N/A | G4: ~ 1 Week | H4: 46223 | I4: 46225 | J4: =_xlfn.DAYS(I4,H4) -> 2 | L4: Owner 1 | M4: Complete
A5: 2 | B5: Agenda and Topic finalization | C5: Draft budget | D5: Budget -> leader input -> execute orders | E5: Estimated budget covering venue, catering, and additional event materials | F5: #1 - Budget estimates depend on the event format, attendance targets, and logistics requirements. | H5: 46225 | I5: 46228 | J5: =_xlfn.DAYS(I5,H5) -> 3 | L5: Owner 3 | M5: In progress
A6: 3 | B6: =Dashboard!$A$11 -> Pre-Event Planning | C6: Set up shared folder and templates | D6: Agenda -> set up place holders for organizing team + external partner and deloitte leadership | E6: Centralized folder created with clear subfolders (e.g., outreach, logistics, materials) and trackers/templates accessible to all team members | F6: N/A | G6: ~ 1 Day | J6: =_xlfn.DAYS(I6,H6) -> 0 | L6: Owner 2 | M6: Complete
A7: 4 | B7: =Dashboard!$A$11 -> Pre-Event Planning | C7: Send internal invite with key dates and placeholders | E7: Send meeting invite to organizing team. Internal calendar placeholders for the event | F7: N/A | J7: =_xlfn.DAYS(I7,H7) -> 0 | L7: Owner 1
A8: 5 | B8: =Dashboard!$A$11 -> Pre-Event Planning | C8: Create group chat on Teams for Deloitte event organizers | E8: Teams chat created with all event organizers added | F8: N/A | J8: =_xlfn.DAYS(I8,H8) -> 0 | L8: Owner 1
A9: 6 | B9: =Dashboard!$A$11 -> Pre-Event Planning | C9: Schedule weekly stand up calls with event organizers | E9: Confirm tasks has been completed, and next steps | F9: N/A | J9: =_xlfn.DAYS(I9,H9) -> 0
A10: 7 | B10: =Dashboard!$A$11 -> Pre-Event Planning | C10: If working with vendor, clarify responsibilities and expectations | D10: move before milestone event (before finalized agenda) | E10: Vendor roles, attendee targets, and responsibilities clearly agreed | F10: #1, #3 - Event objectives and budget constraints should be understood before engaging vendors. | G10: ~ 1 Week | J10: =_xlfn.DAYS(I10,H10) -> 0
A11: 8 | B11: =Dashboard!$A$12 -> Outreach & Registration | C11: Update Internal attendee coordination | E11: Identify target attendees, align with partners/leaders, and finalize the internal outreach list. | F11: N/A | G11: On going | J11: =_xlfn.DAYS(I11,H11) -> 0
A12: 9 | B12: =Dashboard!$A$12 -> Outreach & Registration | C12: External attendee coordination (if applicable) | E12: Coordinate with the vendor to identify, review, and finalize the external attendee list. | F12: #7 - Vendor responsibilities and attendee expectations must be agreed upon before coordinating outreach. | J12: =_xlfn.DAYS(I12,H12) -> 0
A13: 10 | B13: Agenda and Topic finalization | C13: Draft Agenda | E13: Draft agenda including the event objectives, session topics, timings | F13: N/A | G13: ~ 2 Week | J13: =_xlfn.DAYS(I13,H13) -> 0
A14: 11 | B14: Agenda and Topic finalization | C14: Review and approval of the agenda | E14: Draft agenda approved by leadership with feedback incorporated | F14: N/A | J14: =_xlfn.DAYS(I14,H14) -> 0
A15: 12 | B15: Agenda and Topic finalization | C15: Draft calendar invite | E15: Calendar invite drafted with approved event details, agenda, date, time, venue and attendees instruction | F15: N/A | G15: ~ 1 Week | J15: =_xlfn.DAYS(I15,H15) -> 0
A16: 13 | B16: Agenda and Topic finalization | C16: Send calendar invite | E16: Invite distributed to attendees, with successful delivery confirmed | F16: #11, #12 - Calendar invite and agenda must be finalized before distribution. | J16: =_xlfn.DAYS(I16,H16) -> 0
A17: 14 | B17: =Dashboard!$A$12 -> Outreach & Registration | C17: Track registrations | D17: Set up tracker (i.e., DU tracker) -> collect excel [ASK RILEY] -> send partner and leadership latest list (dates on when its sent out, T-1,T-3 etc.) | E17: Tracker is up to date with confirmed attendees and follow-ups | F17: #13 - Registration tracking begins once invitations are sent. | G17: On going | J17: =_xlfn.DAYS(I17,H17) -> 0
A18: 15 | B18: Agenda and Topic finalization | C18: Confirm catering | E18: Food and drinks scheduled and ready 15 minutes before the designated serving time | F18: #14 - Catering requirements depend on expected attendance. | G18: On going | J18: =_xlfn.DAYS(I18,H18) -> 0
A19: 16 | B19: Agenda and Topic finalization | C19: Book event space, Book room for food and beverage | E19: Main room booked with seating layout (pods) and request for lanyard box for attendees to drop their lanyards after event | F19: #1 - Venue requirements depend on approved event format and attendance targets. | G19: ~ 2 Days | J19: =_xlfn.DAYS(I19,H19) -> 0
A20: 17 | B20: Agenda and Topic finalization | E20: Rooms booked for cocktail/dinner hours, request set up 15min prior to scheduled time | F20: #7 - Food and beverage orders depend on attendance estimates. | J20: =_xlfn.DAYS(I20,H20) -> 0
A21: 18 | B21: =Dashboard!$A$13 -> Pre-Event Logistics | C21: Prepare draft signage | E21: Signage draft in line with Deloitte standards | F21: N/A | G21: ~1 Week | J21: =_xlfn.DAYS(I21,H21) -> 0
B22: =Dashboard!$A$13 -> Pre-Event Logistics | C22: Review and approval of signage with leadership | E22: Signage approved by leadership and IT | F22: N/A
A23: 19 | B23: =Dashboard!$A$13 -> Pre-Event Logistics | C23: Coordinate IT support (videoconferencing capabilities) | E23: IT confirmed to support AV and arrive 30min before event start time | F23: #16 - IT requirements depend on the selected venue and event format. | J23: =_xlfn.DAYS(I23,H23) -> 0
A24: 20 | B24: =Dashboard!$A$13 -> Pre-Event Logistics | C24: Signage (30min before and 30min after event start) | E24: Signage placed 30min before registration opens and 30min after event start time | F24: N/A | J24: =_xlfn.DAYS(I24,H24) -> 0
A25: 21 | B25: =Dashboard!$A$13 -> Pre-Event Logistics | C25: Book registration table | D25: Put all bookings together | E25: Lobby registration table requested and confirmed | F25: N/A | J25: =_xlfn.DAYS(I25,H25) -> 0
A26: 22 | B26: Agenda and Topic finalization | C26: Draft and assign presentation materials to appropriate individual | E26: Draft presentation materials completed, with each slide assigned to the appropriate individual for content development and review. | F26: N/A | J26: =_xlfn.DAYS(I26,H26) -> 0
C27: Review and approval of presentation materials with leadership (Stanley etc.)
A28: 23 | B28: =Dashboard!$A$14 -> 1 Week Prior Event Planning | C28: Review and approval of presentation materials with leadership (Lisa, Kevin etc.) | E28: Presentation materials reviewed by leadership, feedback incorporated, and final approval received for presentation at the event. | F28: #22 - Completion of the presentation materials | G28: ~ 2 Week | J28: =_xlfn.DAYS(I28,H28) -> 0
A29: 24 | B29: =Dashboard!$A$14 -> 1 Week Prior Event Planning | C29: Review Materials (Final QA) | E29: Confirm slide materials has consistent formatting | F29: #22 - Completion of the presentation materials | J29: =_xlfn.DAYS(I29,H29) -> 0
A30: 25 | B30: =Dashboard!$A$14 -> 1 Week Prior Event Planning | C30: Follow up partners for attendees | D30: Sending excel attendees | E30: Follow up with partner to complete and confirm the attendees | F30: N/A | G30: ~ 1 Week | J30: =_xlfn.DAYS(I30,H30) -> 0
A31: 26 | B31: Event Execution Logistics | C31: Confirm Deloitte moderator | E31: Select 1 or 2 individual as a moderator to introduce speakers | F31: N/A | J31: =_xlfn.DAYS(I31,H31) -> 0
A32: 27 | B32: Event Execution Logistics | C32: Prepare questions for Q&A | E32: Set of 12 approved questions ready to guide discussion | F32: N/A | J32: =_xlfn.DAYS(I32,H32) -> 0
A33: 28 | B33: Event Execution Logistics | C33: Do a dry run with partners (handoffs, how long each speak etc.) | D33: show materials, during the meeting the timekeeper will give you 5min signage for remaining, speaking order | E33: Full dry run with speakers and moderators completed with timing and transitions confirmed | F33: #23, #25 – Materials, speaker assignments, and Q&A topics must be finalized before rehearsal. | J33: =_xlfn.DAYS(I33,H33) -> 0
A34: 29 | B34: Event Execution Logistics | C34: Place order for lanyards, podium pass, name trays | E34: Confirm and share the confirmation email with the team. Order 10 extra lanyards | F34: #14 - Attendance estimates are needed to determine quantities. | G34: On going | J34: =_xlfn.DAYS(I34,H34) -> 0
A35: 30 | B35: Event Execution Logistics | C35: Place order for name tags | E35: Confirm and share the confirmation email with the team. Order 10 blank name tags | F35: #14 - Attendance estimates are needed to determine quantities. | J35: =_xlfn.DAYS(I35,H35) -> 0
A36: 31 | B36: Event Execution Logistics | C36: Draft 'thank you' email | D36: Once agenda is finalized | E36: Draft 'thank you' email including the key discussion topics | F36: N/A | G36: ~ 3 Days | J36: =_xlfn.DAYS(I36,H36) -> 0
A37: 32 | B37: Event Execution Logistics | C37: Review and approval of 'thank you' email | E37: Draft 'thank you' email approved by leadership with feedback incorporated | F37: N/A | J37: =_xlfn.DAYS(I37,H37) -> 0
A38: 33 | B38: Event Execution Logistics | C38: Assign note takers for meeting summary (Q&A) | E38: Draft summary of questions and answers during the presentation | F38: N/A | G38: ~ 1 Day | J38: =_xlfn.DAYS(I38,H38) -> 0
A39: 34 | B39: Day of roles | C39: Attendee Flow Coordinator (if necessary) | E39: Escort attendees from one room to another | F39: N/A | J39: =_xlfn.DAYS(I39,H39) -> 0
A40: 35 | B40: Day of roles | C40: Timekeeper (align signage with speakers) | E40: Provide a heads-up when speakers have 5 minutes left. Confirm with speakers the signal that will be used | F40: N/A | J40: =_xlfn.DAYS(I40,H40) -> 0
...

Sheet Reference
A1: Activities | B1: Links | C1: Notes
A2: Register external guests | B2: Catalog Item - MySupport
A3: For videoconferencing capabilities and to arrange any other AV needs | B3: Meeting and Conference On Site or Virtual IT Support - MySupport
A4: Print name tags | B4: Print Service Request - MySupport | C4: - Request for 10 blank name tags -Contact gtaprintshop@deloitte.ca for any questions
A5: Request for lanyards, podium pass, name trays | B5: Lanyards and Other Pass Card Accessories - MySupport | C5: - Lanyards, podium pass and name trays can only be picked up from the Security on the day of the event - Each name trays can hold 50 name tags - Request for 10 extra name tags
